Workbook

Sheet DATA
A1: STOK OPNAME PERSEDIAN BAHAN BAKU MARET
A3: NO | B3: KODE | C3: NAMA BARANG | D3: SATUAN | E3: HARGA BARANG | F3: STOK AWAL | G3: IN | H3: OUT | I3: IN | J3: OUT | K3: IN | L3: OUT | M3: IN | N3: OUT | O3: IN | P3: OUT | Q3: IN | R3: OUT | S3: IN | T3: OUT | U3: IN | V3: OUT | W3: IN | X3: OUT | Y3: SISA STOK | Z3: NILAI PERSEDIAAN AKHIR
B4: BARANG | G4: 46113 | H4: 46113 | I4: 46114 | J4: 46114 | K4: 46115 | L4: 46115 | M4: 46116 | N4: 46116 | O4: 46117 | P4: 46117 | Q4: 46118 | R4: 46118 | S4: 46119 | T4: 46119 | U4: 46120 | V4: 46120 | W4: 46121 | X4: 46121
B5: BB-001 | C5: BERAS 10kg | D5: Sak | E5: 178000 | F5: 6 | H5: 4 | K5: 0 | L5: 0 | Y5: =F5+G5-H5+I5-J5+K5-L5+M5-N5+O5-P5+Q5-R5+S5-T5+U5-V5+W5-X5 -> 2 | Z5: =E5*Y5 -> 356000
B6: BB-002 | C6: MINYAK GORENG | D6: pcs | E6: 32000 | F6: 14 | H6: 10 | Y6: =F6+G6-H6+I6-J6+K6-L6+M6-N6+O6-P6+Q6-R6+S6-T6+U6-V6+W6-X6 -> 4 | Z6: =E6*Y6 -> 128000
B7: BB-003 | C7: SEGITIGA BIRU | D7: pcs | E7: 14000 | F7: 9 | H7: 2 | Y7: =F7+G7-H7+I7-J7+K7-L7+M7-N7+O7-P7+Q7-R7+S7-T7+U7-V7+W7-X7 -> 7 | Z7: =E7*Y7 -> 98000
B8: BB-004 | C8: TEPUNG TAPIOKA | D8: pcs | E8: 11000 | F8: 14 | H8: 2 | Y8: =F8+G8-H8+I8-J8+K8-L8+M8-N8+O8-P8+Q8-R8+S8-T8+U8-V8+W8-X8 -> 12 | Z8: =E8*Y8 -> 132000
B9: BB-005 | C9: TEPUNG BERAS | D9: pcs | E9: 9000 | F9: 13 | Y9: =F9+G9-H9+I9-J9+K9-L9+M9-N9+O9-P9+Q9-R9+S9-T9+U9-V9+W9-X9 -> 13 | Z9: =E9*Y9 -> 117000
B10: BB-006 | C10: TEPUNG KOBE | D10: pcs | E10: 23000 | F10: 19 | Y10: =F10+G10-H10+I10-J10+K10-L10+M10-N10+O10-P10+Q10-R10+S10-T10+U10-V10+W10-X10 -> 19 | Z10: =E10*Y10 -> 437000
B11: BB-007 | C11: MASAKO | D11: pcs | E11: 34000 | F11: 12 | Y11: =F11+G11-H11+I11-J11+K11-L11+M11-N11+O11-P11+Q11-R11+S11-T11+U11-V11+W11-X11 -> 12 | Z11: =E11*Y11 -> 408000
B12: BB-008 | C12: AJINAMOTO | D12: pcs | E12: 46000 | F12: 7 | H12: 1 | Y12: =F12+G12-H12+I12-J12+K12-L12+M12-N12+O12-P12+Q12-R12+S12-T12+U12-V12+W12-X12 -> 6 | Z12: =E12*Y12 -> 276000
B13: BB-009 | C13: GARAM | D13: pcs | E13: 5000 | F13: 7 | G13: 20 | Y13: =F13+G13-H13+I13-J13+K13-L13+M13-N13+O13-P13+Q13-R13+S13-T13+U13-V13+W13-X13 -> 27 | Z13: =E13*Y13 -> 135000
B14: BB-010 | C14: MAIZENAKU | D14: pcs | E14: 25000 | F14: 2 | Y14: =F14+G14-H14+I14-J14+K14-L14+M14-N14+O14-P14+Q14-R14+S14-T14+U14-V14+W14-X14 -> 2 | Z14: =E14*Y14 -> 50000
B15: BB-011 | C15: MENTEGA BALOK | D15: pcs | E15: 11000 | F15: 9 | G15: 30 | H15: 3 | Y15: =F15+G15-H15+I15-J15+K15-L15+M15-N15+O15-P15+Q15-R15+S15-T15+U15-V15+W15-X15 -> 36 | Z15: =E15*Y15 -> 396000
B16: BB-012 | C16: BAWANG GORENG | D16: pcs | E16: 9000 | F16: 16 | H16: 3 | Y16: =F16+G16-H16+I16-J16+K16-L16+M16-N16+O16-P16+Q16-R16+S16-T16+U16-V16+W16-X16 -> 13 | Z16: =E16*Y16 -> 117000
B17: BB-013 | C17: TERASI UDANG | D17: pack | E17: 10000 | F17: 0 | G17: 5 | Y17: =F17+G17-H17+I17-J17+K17-L17+M17-N17+O17-P17+Q17-R17+S17-T17+U17-V17+W17-X17 -> 5 | Z17: =E17*Y17 -> 50000
B18: BB-014 | C18: PEWARNA PANGAN MERAH CABE | D18: pcs | E18: 5000 | F18: 4 | G18: 30 | Y18: =F18+G18-H18+I18-J18+K18-L18+M18-N18+O18-P18+Q18-R18+S18-T18+U18-V18+W18-X18 -> 34 | Z18: =E18*Y18 -> 170000
B19: BB-015 | C19: KERUPUK PESTA | D19: pcs | E19: 150000 | F19: 1 | Y19: =F19+G19-H19+I19-J19+K19-L19+M19-N19+O19-P19+Q19-R19+S19-T19+U19-V19+W19-X19 -> 1 | Z19: =E19*Y19 -> 150000
B20: BB-016 | C20: KERUPUK FINNA | D20: pcs | E20: 28000 | F20: 27 | H20: 2 | Y20: =F20+G20-H20+I20-J20+K20-L20+M20-N20+O20-P20+Q20-R20+S20-T20+U20-V20+W20-X20 -> 25 | Z20: =E20*Y20 -> 700000
B21: BB-017 | C21: MUSHROOM | D21: pcs | E21: 20000 | F21: 4 | H21: 1 | Y21: =F21+G21-H21+I21-J21+K21-L21+M21-N21+O21-P21+Q21-R21+S21-T21+U21-V21+W21-X21 -> 3 | Z21: =E21*Y21 -> 60000
B22: BB-018 | C22: HERCULES | D22: pcs | E22: 38000 | F22: 3 | Y22: =F22+G22-H22+I22-J22+K22-L22+M22-N22+O22-P22+Q22-R22+S22-T22+U22-V22+W22-X22 -> 3 | Z22: =E22*Y22 -> 114000
B23: BB-019 | C23: MADU TJ | D23: pcs | E23: 62000 | F23: 4 | Y23: =F23+G23-H23+I23-J23+K23-L23+M23-N23+O23-P23+Q23-R23+S23-T23+U23-V23+W23-X23 -> 4 | Z23: =E23*Y23 -> 248000
B24: BB-020 | C24: SODA KUE | D24: pcs | E24: 10000 | F24: 1 | Y24: =F24+G24-H24+I24-J24+K24-L24+M24-N24+O24-P24+Q24-R24+S24-T24+U24-V24+W24-X24 -> 1 | Z24: =E24*Y24 -> 10000
B25: BB-021 | C25: CUKA DAPUR | D25: botol | E25: 12000 | F25: 1 | Y25: =F25+G25-H25+I25-J25+K25-L25+M25-N25+O25-P25+Q25-R25+S25-T25+U25-V25+W25-X25 -> 1 | Z25: =E25*Y25 -> 12000
B26: BB-022 | C26: SAUS TIRAM CAP PANDA | D26: botol | E26: 91000 | F26: 12 | H26: 2 | Y26: =F26+G26-H26+I26-J26+K26-L26+M26-N26+O26-P26+Q26-R26+S26-T26+U26-V26+W26-X26 -> 10 | Z26: =E26*Y26 -> 910000
B27: BB-023 | C27: KECAP INGGRIS | D27: botol | E27: 52000 | F27: 5 | Y27: =F27+G27-H27+I27-J27+K27-L27+M27-N27+O27-P27+Q27-R27+S27-T27+U27-V27+W27-X27 -> 5 | Z27: =E27*Y27 -> 260000
B28: BB-024 | C28: ANCIU PENYEDAP MAKANAN | D28: botol | E28: 40000 | F28: 2 | Y28: =F28+G28-H28+I28-J28+K28-L28+M28-N28+O28-P28+Q28-R28+S28-T28+U28-V28+W28-X28 -> 2 | Z28: =E28*Y28 -> 80000
B29: BB-025 | C29: KECAP HITAM | D29: botol | E29: 0 | F29: 6 | Y29: =F29+G29-H29+I29-J29+K29-L29+M29-N29+O29-P29+Q29-R29+S29-T29+U29-V29+W29-X29 -> 6 | Z29: =E29*Y29 -> 0
B30: BB-026 | C30: MINYAK WIJEN | D30: botol | E30: 47000 | F30: 2 | G30: 24 | H30: 1 | Y30: =F30+G30-H30+I30-J30+K30-L30+M30-N30+O30-P30+Q30-R30+S30-T30+U30-V30+W30-X30 -> 25 | Z30: =E30*Y30 -> 1175000
B31: BB-027 | C31: KECAP IKAN FINNA | D31: botol | E31: 0 | F31: 5 | Y31: =F31+G31-H31+I31-J31+K31-L31+M31-N31+O31-P31+Q31-R31+S31-T31+U31-V31+W31-X31 -> 5 | Z31: =E31*Y31 -> 0
B32: BB-028 | C32: SAUS RAJA RASA | D32: botol | E32: 40000 | F32: 4 | Y32: =F32+G32-H32+I32-J32+K32-L32+M32-N32+O32-P32+Q32-R32+S32-T32+U32-V32+W32-X32 -> 4 | Z32: =E32*Y32 -> 160000
B33: BB-029 | C33: KECAP IKAN ROYAL | D33: botol | E33: 60000 | F33: 3 | Y33: =F33+G33-H33+I33-J33+K33-L33+M33-N33+O33-P33+Q33-R33+S33-T33+U33-V33+W33-X33 -> 3 | Z33: =E33*Y33 -> 180000
B34: BB-030 | C34: KECAP ASIN | D34: botol | E34: 0 | F34: 3 | Y34: =F34+G34-H34+I34-J34+K34-L34+M34-N34+O34-P34+Q34-R34+S34-T34+U34-V34+W34-X34 -> 3 | Z34: =E34*Y34 -> 0
B35: BB-031 | C35: KECAP BANGO | D35: pcs | E35: 15000 | F35: 3 | Y35: =F35+G35-H35+I35-J35+K35-L35+M35-N35+O35-P35+Q35-R35+S35-T35+U35-V35+W35-X35 -> 3 | Z35: =E35*Y35 -> 45000
B36: BB-032 | C36: SAUS ABC SAMBEL ASLI | D36: pcs | E36: 32900 | F36: 15 | Y36: =F36+G36-H36+I36-J36+K36-L36+M36-N36+O36-P36+Q36-R36+S36-T36+U36-V36+W36-X36 -> 15 | Z36: =E36*Y36 -> 493500
B37: BB-033 | C37: SAUS ABC TOMAT | D37: pcs | E37: 22000 | F37: 6 | Y37: =F37+G37-H37+I37-J37+K37-L37+M37-N37+O37-P37+Q37-R37+S37-T37+U37-V37+W37-X37 -> 6 | Z37: =E37*Y37 -> 132000
B38: BB-034 | C38: SANTAN KARA SUN | D38: pcs | E38: 18000 | F38: 6 | Y38: =F38+G38-H38+I38-J38+K38-L38+M38-N38+O38-P38+Q38-R38+S38-T38+U38-V38+W38-X38 -> 6 | Z38: =E38*Y38 -> 108000
B39: BB-035 | C39: SAUS TOMAT CAP BAGONG | D39: pcs | E39: 0 | F39: 11 | Y39: =F39+G39-H39+I39-J39+K39-L39+M39-N39+O39-P39+Q39-R39+S39-T39+U39-V39+W39-X39 -> 11 | Z39: =E39*Y39 -> 0
B40: BB-036 | C40: SUSU UHT | D40: pcs | E40: 19000 | F40: 0 | Y40: =F40+G40-H40+I40-J40+K40-L40+M40-N40+O40-P40+Q40-R40+S40-T40+U40-V40+W40-X40 -> 0 | Z40: =E40*Y40 -> 0
B41: BB-037 | C41: MAX CREAMER | D41: pcs | E41: 49000 | F41: 3 | H41: 1 | Y41: =F41+G41-H41+I41-J41+K41-L41+M41-N41+O41-P41+Q41-R41+S41-T41+U41-V41+W41-X41 -> 2 | Z41: =E41*Y41 -> 98000
...

Sheet BARANG MASUK 
A1: BARANG MASUK
A3: TANGGAL | B3: KODE BARANG | C3: NAMA BARANG | D3: JUMLAH MASUK
B4: BB-002 | C4: =VLOOKUP(Table1[[#This Row],[KODE BARANG ]],DATA!B5:C78,2,FALSE) -> MINYAK GORENG | D4: 50
A5: 23/03/2026 | B5: BB-002 | C5: =VLOOKUP(Table1[[#This Row],[KODE BARANG ]],DATA!B6:C78,2,FALSE) -> MINYAK GORENG
B6: BB-003 | C6: =VLOOKUP(Table1[[#This Row],[KODE BARANG ]],DATA!B7:C79,2,FALSE) -> SEGITIGA BIRU | D6: 0
B7: BB-004 | C7: =VLOOKUP(Table1[[#This Row],[KODE BARANG ]],DATA!B8:C80,2,FALSE) -> TEPUNG TAPIOKA | D7: 0
B8: BB-005 | C8: =VLOOKUP(Table1[[#This Row],[KODE BARANG ]],DATA!B9:C81,2,FALSE) -> TEPUNG BERAS | D8: 0
B9: BB-006 | C9: =VLOOKUP(Table1[[#This Row],[KODE BARANG ]],DATA!B10:C82,2,FALSE) -> TEPUNG KOBE | D9: 0
B10: BB-007 | C10: =VLOOKUP(Table1[[#This Row],[KODE BARANG ]],DATA!B11:C83,2,FALSE) -> MASAKO | D10: 12
B11: BB-008 | C11: =VLOOKUP(Table1[[#This Row],[KODE BARANG ]],DATA!B12:C84,2,FALSE) -> AJINAMOTO | D11: 0
B12: BB-009 | C12: =VLOOKUP(Table1[[#This Row],[KODE BARANG ]],DATA!B13:C85,2,FALSE) -> GARAM | D12: 0
B13: BB-010 | C13: =VLOOKUP(Table1[[#This Row],[KODE BARANG ]],DATA!B14:C87,2,FALSE) -> MAIZENAKU
B14: BB-011 | C14: =VLOOKUP(Table1[[#This Row],[KODE BARANG ]],DATA!B15:C88,2,FALSE) -> MENTEGA BALOK
B15: BB-012 | C15: =VLOOKUP(Table1[[#This Row],[KODE BARANG ]],DATA!B16:C89,2,FALSE) -> BAWANG GORENG
B16: BB-013 | C16: =VLOOKUP(Table1[[#This Row],[KODE BARANG ]],DATA!B17:C90,2,FALSE) -> TERASI UDANG
B17: BB-014 | C17: =VLOOKUP(Table1[[#This Row],[KODE BARANG ]],DATA!B18:C91,2,FALSE) -> PEWARNA PANGAN MERAH CABE
B18: BB-015 | C18: =VLOOKUP(Table1[[#This Row],[KODE BARANG ]],DATA!B19:C92,2,FALSE) -> KERUPUK PESTA
B19: BB-016 | C19: =VLOOKUP(Table1[[#This Row],[KODE BARANG ]],DATA!B20:C93,2,FALSE) -> KERUPUK FINNA
B20: BB-017 | C20: =VLOOKUP(Table1[[#This Row],[KODE BARANG ]],DATA!B21:C94,2,FALSE) -> MUSHROOM
B21: BB-018 | C21: =VLOOKUP(Table1[[#This Row],[KODE BARANG ]],DATA!B22:C95,2,FALSE) -> HERCULES
B22: BB-019 | C22: =VLOOKUP(Table1[[#This Row],[KODE BARANG ]],DATA!B23:C96,2,FALSE) -> MADU TJ
B23: BB-020 | C23: =VLOOKUP(Table1[[#This Row],[KODE BARANG ]],DATA!B24:C97,2,FALSE) -> SODA KUE
B24: BB-021 | C24: =VLOOKUP(Table1[[#This Row],[KODE BARANG ]],DATA!B25:C98,2,FALSE) -> CUKA DAPUR
B25: BB-022 | C25: =VLOOKUP(Table1[[#This Row],[KODE BARANG ]],DATA!B26:C99,2,FALSE) -> SAUS TIRAM CAP PANDA | D25: 6
B26: BB-023 | C26: =VLOOKUP(Table1[[#This Row],[KODE BARANG ]],DATA!B27:C100,2,FALSE) -> KECAP INGGRIS
B27: BB-024 | C27: =VLOOKUP(Table1[[#This Row],[KODE BARANG ]],DATA!B28:C101,2,FALSE) -> ANCIU PENYEDAP MAKANAN
B28: BB-025 | C28: =VLOOKUP(Table1[[#This Row],[KODE BARANG ]],DATA!B29:C102,2,FALSE) -> KECAP HITAM
B29: BB-026 | C29: =VLOOKUP(Table1[[#This Row],[KODE BARANG ]],DATA!B30:C103,2,FALSE) -> MINYAK WIJEN
B30: BB-027 | C30: =VLOOKUP(Table1[[#This Row],[KODE BARANG ]],DATA!B31:C104,2,FALSE) -> KECAP IKAN FINNA
B31: BB-028 | C31: =VLOOKUP(Table1[[#This Row],[KODE BARANG ]],DATA!B32:C105,2,FALSE) -> SAUS RAJA RASA
B32: BB-029 | C32: =VLOOKUP(Table1[[#This Row],[KODE BARANG ]],DATA!B33:C106,2,FALSE) -> KECAP IKAN ROYAL
B33: BB-030 | C33: =VLOOKUP(Table1[[#This Row],[KODE BARANG ]],DATA!B34:C106,2,FALSE) -> KECAP ASIN
B34: BB-031 | C34: =VLOOKUP(Table1[[#This Row],[KODE BARANG ]],DATA!B35:C107,2,FALSE) -> KECAP BANGO
B35: BB-032 | C35: =VLOOKUP(Table1[[#This Row],[KODE BARANG ]],DATA!B36:C108,2,FALSE) -> SAUS ABC SAMBEL ASLI
B36: BB-033 | C36: =VLOOKUP(Table1[[#This Row],[KODE BARANG ]],DATA!B37:C109,2,FALSE) -> SAUS ABC TOMAT
B37: BB-034 | C37: =VLOOKUP(Table1[[#This Row],[KODE BARANG ]],DATA!B38:C110,2,FALSE) -> SANTAN KARA SUN
B38: BB-035 | C38: =VLOOKUP(Table1[[#This Row],[KODE BARANG ]],DATA!B39:C111,2,FALSE) -> SAUS TOMAT CAP BAGONG
A39: 23/03/2026 | B39: BB-036 | C39: =VLOOKUP(Table1[[#This Row],[KODE BARANG ]],DATA!B40:C112,2,FALSE) -> SUSU UHT
A40: 23/03/2026 | B40: BB-037 | C40: =VLOOKUP(Table1[[#This Row],[KODE BARANG ]],DATA!B41:C113,2,FALSE) -> MAX CREAMER
B41: BB-038 | C41: =VLOOKUP(Table1[[#This Row],[KODE BARANG ]],DATA!B42:C114,2,FALSE) -> SUSU EVAPORASI
...

Sheet Sheet1
A1: LAPORAN STOK BARANG HARIAN
D2: 23 OKTOBER 2026
A3: NO | B3: KODE BARANG | C3: NAMA BARANG | D3: HARGA BARANG | E3: STOK AWAL | F3: MASUK | G3: KELUAR | H3: SISA STOK | I3: NILAI PERSEDIAAN AKHIR
B4: BB-001 | C4: =VLOOKUP(Table14[[#This Row],[KODE BARANG ]],DATA!B5:C78,2,FALSE) -> BERAS 10kg | D4: 0 | F4: 0 | G4: 2
A5: 23/03/2026 | B5: BB-002 | C5: =VLOOKUP(Table14[[#This Row],[KODE BARANG ]],DATA!B6:C78,2,FALSE) -> MINYAK GORENG | D5: 41000
B6: BB-003 | C6: =VLOOKUP(Table14[[#This Row],[KODE BARANG ]],DATA!B7:C79,2,FALSE) -> SEGITIGA BIRU | D6: 14000 | F6: 0 | G6: 1
B7: BB-004 | C7: =VLOOKUP(Table14[[#This Row],[KODE BARANG ]],DATA!B8:C80,2,FALSE) -> TEPUNG TAPIOKA | D7: 11000 | F7: 0
B8: BB-005 | C8: =VLOOKUP(Table14[[#This Row],[KODE BARANG ]],DATA!B9:C81,2,FALSE) -> TEPUNG BERAS | D8: 9000 | F8: 0 | G8: 1
B9: BB-006 | C9: =VLOOKUP(Table14[[#This Row],[KODE BARANG ]],DATA!B10:C82,2,FALSE) -> TEPUNG KOBE | D9: 23000 | F9: 0
B10: BB-007 | C10: =VLOOKUP(Table14[[#This Row],[KODE BARANG ]],DATA!B11:C83,2,FALSE) -> MASAKO | D10: 34000 | F10: 12 | G10: 1
B11: BB-008 | C11: =VLOOKUP(Table14[[#This Row],[KODE BARANG ]],DATA!B12:C84,2,FALSE) -> AJINAMOTO | D11: 46000 | F11: 0 | G11: 1
B12: BB-009 | C12: =VLOOKUP(Table14[[#This Row],[KODE BARANG ]],DATA!B13:C85,2,FALSE) -> GARAM | D12: 0 | F12: 0 | G12: 1
B13: BB-010 | C13: =VLOOKUP(Table14[[#This Row],[KODE BARANG ]],DATA!B14:C87,2,FALSE) -> MAIZENAKU | D13: 25000
B14: BB-011 | C14: =VLOOKUP(Table14[[#This Row],[KODE BARANG ]],DATA!B15:C88,2,FALSE) -> MENTEGA BALOK | D14: 0
B15: BB-012 | C15: =VLOOKUP(Table14[[#This Row],[KODE BARANG ]],DATA!B16:C89,2,FALSE) -> BAWANG GORENG | D15: 9000
B16: BB-013 | C16: =VLOOKUP(Table14[[#This Row],[KODE BARANG ]],DATA!B17:C90,2,FALSE) -> TERASI UDANG | D16: 10000 | G16: 1
B17: BB-014 | C17: =VLOOKUP(Table14[[#This Row],[KODE BARANG ]],DATA!B18:C91,2,FALSE) -> PEWARNA PANGAN MERAH CABE | D17: 0
B18: BB-015 | C18: =VLOOKUP(Table14[[#This Row],[KODE BARANG ]],DATA!B19:C92,2,FALSE) -> KERUPUK PESTA | D18: 0
B19: BB-016 | C19: =VLOOKUP(Table14[[#This Row],[KODE BARANG ]],DATA!B20:C93,2,FALSE) -> KERUPUK FINNA | D19: 0
B20: BB-017 | C20: =VLOOKUP(Table14[[#This Row],[KODE BARANG ]],DATA!B21:C94,2,FALSE) -> MUSHROOM | D20: 20000
B21: BB-018 | C21: =VLOOKUP(Table14[[#This Row],[KODE BARANG ]],DATA!B22:C95,2,FALSE) -> HERCULES | D21: 38000 | G21: 1
B22: BB-019 | C22: =VLOOKUP(Table14[[#This Row],[KODE BARANG ]],DATA!B23:C96,2,FALSE) -> MADU TJ | D22: 62000 | G22: 2
B23: BB-020 | C23: =VLOOKUP(Table14[[#This Row],[KODE BARANG ]],DATA!B24:C97,2,FALSE) -> SODA KUE | D23: 0 | G23: 1
B24: BB-021 | C24: =VLOOKUP(Table14[[#This Row],[KODE BARANG ]],DATA!B25:C98,2,FALSE) -> CUKA DAPUR | D24: 12000
B25: BB-022 | C25: =VLOOKUP(Table14[[#This Row],[KODE BARANG ]],DATA!B26:C99,2,FALSE) -> SAUS TIRAM CAP PANDA | D25: 91000 | F25: 6 | G25: 3
B26: BB-023 | C26: =VLOOKUP(Table14[[#This Row],[KODE BARANG ]],DATA!B27:C100,2,FALSE) -> KECAP INGGRIS | D26: 52000
B27: BB-024 | C27: =VLOOKUP(Table14[[#This Row],[KODE BARANG ]],DATA!B28:C101,2,FALSE) -> ANCIU PENYEDAP MAKANAN | D27: 0
B28: BB-025 | C28: =VLOOKUP(Table14[[#This Row],[KODE BARANG ]],DATA!B29:C102,2,FALSE) -> KECAP HITAM | D28: 0
B29: BB-026 | C29: =VLOOKUP(Table14[[#This Row],[KODE BARANG ]],DATA!B30:C103,2,FALSE) -> MINYAK WIJEN | D29: 47000 | G29: 2
B30: BB-027 | C30: =VLOOKUP(Table14[[#This Row],[KODE BARANG ]],DATA!B31:C104,2,FALSE) -> KECAP IKAN FINNA | D30: 0
B31: BB-028 | C31: =VLOOKUP(Table14[[#This Row],[KODE BARANG ]],DATA!B32:C105,2,FALSE) -> SAUS RAJA RASA | D31: 0
B32: BB-029 | C32: =VLOOKUP(Table14[[#This Row],[KODE BARANG ]],DATA!B33:C106,2,FALSE) -> KECAP IKAN ROYAL | D32: 0
B33: BB-030 | C33: =VLOOKUP(Table14[[#This Row],[KODE BARANG ]],DATA!B34:C106,2,FALSE) -> KECAP ASIN | D33: 0
B34: BB-031 | C34: =VLOOKUP(Table14[[#This Row],[KODE BARANG ]],DATA!B35:C107,2,FALSE) -> KECAP BANGO | D34: 0 | G34: 1
B35: BB-032 | C35: =VLOOKUP(Table14[[#This Row],[KODE BARANG ]],DATA!B36:C108,2,FALSE) -> SAUS ABC SAMBEL ASLI | D35: 0
B36: BB-033 | C36: =VLOOKUP(Table14[[#This Row],[KODE BARANG ]],DATA!B37:C109,2,FALSE) -> SAUS ABC TOMAT | D36: 20000
B37: BB-034 | C37: =VLOOKUP(Table14[[#This Row],[KODE BARANG ]],DATA!B38:C110,2,FALSE) -> SANTAN KARA SUN | D37: 18000
B38: BB-035 | C38: =VLOOKUP(Table14[[#This Row],[KODE BARANG ]],DATA!B39:C111,2,FALSE) -> SAUS TOMAT CAP BAGONG | D38: 0
A39: 23/03/2026 | B39: BB-036 | C39: =VLOOKUP(Table14[[#This Row],[KODE BARANG ]],DATA!B40:C112,2,FALSE) -> SUSU UHT | D39: 19000 | G39: 12
A40: 23/03/2026 | B40: BB-037 | C40: =VLOOKUP(Table14[[#This Row],[KODE BARANG ]],DATA!B41:C113,2,FALSE) -> MAX CREAMER | D40: 49000 | G40: 1
...

Sheet BARANG KELUAR
A1: BARANG KELUAR
A3: TANGGAL | B3: KODE BARANG | C3: NAMA BARANG | D3: JUMLAH BARANG
A4: 23/03/2026 | B4: BB-001 | C4: =VLOOKUP(Table2[[#This Row],[KODE BARANG ]],DATA!B5:C78,2,FALSE) -> BERAS 10kg | D4: 2
A5: 23/03/2026 | B5: BB-002 | C5: =VLOOKUP(Table2[[#This Row],[KODE BARANG ]],DATA!B6:C78,2,FALSE) -> MINYAK GORENG
A6: 23/03/2026 | B6: BB-003 | C6: =VLOOKUP(Table2[[#This Row],[KODE BARANG ]],DATA!B7:C79,2,FALSE) -> SEGITIGA BIRU | D6: 1
B7: BB-004 | C7: =VLOOKUP(Table2[[#This Row],[KODE BARANG ]],DATA!B8:C80,2,FALSE) -> TEPUNG TAPIOKA
B8: BB-005 | C8: =VLOOKUP(Table2[[#This Row],[KODE BARANG ]],DATA!B9:C81,2,FALSE) -> TEPUNG BERAS | D8: 1
B9: BB-006 | C9: =VLOOKUP(Table2[[#This Row],[KODE BARANG ]],DATA!B10:C82,2,FALSE) -> TEPUNG KOBE
B10: BB-007 | C10: =VLOOKUP(Table2[[#This Row],[KODE BARANG ]],DATA!B11:C83,2,FALSE) -> MASAKO | D10: 1
A11: 23/03/2026 | B11: BB-008 | C11: =VLOOKUP(Table2[[#This Row],[KODE BARANG ]],DATA!B12:C84,2,FALSE) -> AJINAMOTO | D11: 1
B12: BB-009 | C12: =VLOOKUP(Table2[[#This Row],[KODE BARANG ]],DATA!B13:C85,2,FALSE) -> GARAM | D12: 1
B13: BB-010 | C13: =VLOOKUP(Table2[[#This Row],[KODE BARANG ]],DATA!B14:C86,2,FALSE) -> MAIZENAKU
A14: 23/03/2026 | B14: BB-011 | C14: =VLOOKUP(Table2[[#This Row],[KODE BARANG ]],DATA!B15:C87,2,FALSE) -> MENTEGA BALOK
A15: 23/03/2026 | B15: BB-012 | C15: =VLOOKUP(Table2[[#This Row],[KODE BARANG ]],DATA!B16:C88,2,FALSE) -> BAWANG GORENG
B16: BB-013 | C16: =VLOOKUP(Table2[[#This Row],[KODE BARANG ]],DATA!B17:C89,2,FALSE) -> TERASI UDANG | D16: 1
B17: BB-014 | C17: =VLOOKUP(Table2[[#This Row],[KODE BARANG ]],DATA!B18:C90,2,FALSE) -> PEWARNA PANGAN MERAH CABE
B18: BB-015 | C18: =VLOOKUP(Table2[[#This Row],[KODE BARANG ]],DATA!B19:C91,2,FALSE) -> KERUPUK PESTA
B19: BB-016 | C19: =VLOOKUP(Table2[[#This Row],[KODE BARANG ]],DATA!B20:C92,2,FALSE) -> KERUPUK FINNA
B20: BB-017 | C20: =VLOOKUP(Table2[[#This Row],[KODE BARANG ]],DATA!B21:C93,2,FALSE) -> MUSHROOM
B21: BB-018 | C21: =VLOOKUP(Table2[[#This Row],[KODE BARANG ]],DATA!B22:C94,2,FALSE) -> HERCULES | D21: 1
B22: BB-019 | C22: =VLOOKUP(Table2[[#This Row],[KODE BARANG ]],DATA!B23:C95,2,FALSE) -> MADU TJ | D22: 2
B23: BB-020 | C23: =VLOOKUP(Table2[[#This Row],[KODE BARANG ]],DATA!B24:C96,2,FALSE) -> SODA KUE | D23: 1
B24: BB-021 | C24: =VLOOKUP(Table2[[#This Row],[KODE BARANG ]],DATA!B25:C97,2,FALSE) -> CUKA DAPUR
B25: BB-022 | C25: =VLOOKUP(Table2[[#This Row],[KODE BARANG ]],DATA!B26:C98,2,FALSE) -> SAUS TIRAM CAP PANDA | D25: 3
B26: BB-023 | C26: =VLOOKUP(Table2[[#This Row],[KODE BARANG ]],DATA!B27:C99,2,FALSE) -> KECAP INGGRIS
B27: BB-024 | C27: =VLOOKUP(Table2[[#This Row],[KODE BARANG ]],DATA!B28:C100,2,FALSE) -> ANCIU PENYEDAP MAKANAN
B28: BB-025 | C28: =VLOOKUP(Table2[[#This Row],[KODE BARANG ]],DATA!B29:C101,2,FALSE) -> KECAP HITAM
B29: BB-026 | C29: =VLOOKUP(Table2[[#This Row],[KODE BARANG ]],DATA!B30:C102,2,FALSE) -> MINYAK WIJEN | D29: 2
B30: BB-027 | C30: =VLOOKUP(Table2[[#This Row],[KODE BARANG ]],DATA!B31:C103,2,FALSE) -> KECAP IKAN FINNA
B31: BB-028 | C31: =VLOOKUP(Table2[[#This Row],[KODE BARANG ]],DATA!B32:C104,2,FALSE) -> SAUS RAJA RASA
B32: BB-029 | C32: =VLOOKUP(Table2[[#This Row],[KODE BARANG ]],DATA!B33:C105,2,FALSE) -> KECAP IKAN ROYAL
A33: 23/03/2026 | B33: BB-030 | C33: =VLOOKUP(Table2[[#This Row],[KODE BARANG ]],DATA!B34:C106,2,FALSE) -> KECAP ASIN
B34: BB-031 | C34: =VLOOKUP(Table2[[#This Row],[KODE BARANG ]],DATA!B35:C106,2,FALSE) -> KECAP BANGO | D34: 1
B35: BB-032 | C35: =VLOOKUP(Table2[[#This Row],[KODE BARANG ]],DATA!B36:C107,2,FALSE) -> SAUS ABC SAMBEL ASLI
B36: BB-033 | C36: =VLOOKUP(Table2[[#This Row],[KODE BARANG ]],DATA!B37:C108,2,FALSE) -> SAUS ABC TOMAT
B37: BB-034 | C37: =VLOOKUP(Table2[[#This Row],[KODE BARANG ]],DATA!B38:C109,2,FALSE) -> SANTAN KARA SUN
B38: BB-035 | C38: =VLOOKUP(Table2[[#This Row],[KODE BARANG ]],DATA!B39:C110,2,FALSE) -> SAUS TOMAT CAP BAGONG
A39: 23/03/2026 | B39: BB-036 | C39: =VLOOKUP(Table2[[#This Row],[KODE BARANG ]],DATA!B40:C111,2,FALSE) -> SUSU UHT | D39: 12
B40: BB-037 | C40: =VLOOKUP(Table2[[#This Row],[KODE BARANG ]],DATA!B41:C112,2,FALSE) -> MAX CREAMER | D40: 1
B41: BB-038 | C41: =VLOOKUP(Table2[[#This Row],[KODE BARANG ]],DATA!B42:C113,2,FALSE) -> SUSU EVAPORASI | D41: 1
...
